Workbook

Sheet Visão 360°
A1: VISÃO 360° | Diagnóstico e Plano Patrimonial
A3: 1. INFORMAÇÕES DO CLIENTE
A4: Nome | B4: Perfil do Investidor | C4: Nascimento | D4: Idade | E4: Profissão
B5: =B56 -> Conservador | C5: 31456 | D5: =IF(C5="","",(TODAY()-C5)/365) -> 40.09863 | E5: Atleta de Voleibol
A7: 2. INFORMAÇÕES FAMILIARES
A8: Nome | B8: Parentesco | C8: Nascimento | D8: Idade | E8: Profissão
D9: =IF(C9="","",(TODAY()-C9)/365)
D10: =IF(C10="","",(TODAY()-C10)/365)
D11: =IF(C11="","",(TODAY()-C11)/365)
D12: =IF(C12="","",(TODAY()-C12)/365)
A14: 3. BALANÇO PATRIMONIAL
A15: Ativos - Financeiros (bancos, corretoras etc.) | B15: 388000 | C15: Observações / Comentários
A16: Ativos - Imobilizados (imóveis, carros etc.) | B16: 0 | C16: Exemplo: possui previdência fora
A17: Ativos - Outros (comente) | B17: 0
A18: Ativos - Total | B18: =SUM(B15:B17) -> 388000
A19: Passivos - Empréstimos | B19: 0
A20: Passivos - Financiamentos | B20: 400000
A21: Passivos - Consórcios | B21: 0
A22: Passivos - Outros (comente) | B22: 0
A23: Passivos - Total | B23: =SUM(B19:B22) -> 400000
A24: Patrimônio Líquido | B24: =B18-B23 -> -12000
A26: 4. DADOS ORÇAMENTÁRIOS
A27: Regime de trabalho | B27: Autônomo | C27: Observações / Comentários
A28: Tipo de declaração de IR | B28: Simplificada | C28: Salário: 200k/9
A29: Ganho mensal aproximado | B29: 16666
A30: Ganho anual aproximado | B30: =IF(OR(B27="CLT",B27="Funcionário Público"), IF(ISNUMBER(B29),B29*13,""), IF(OR(B27="Autônomo",B27="Empresário"), IF(ISNUMBER(B29),B29*12,""), IF(B27="Misto","Observação","") ) ) -> 199992
A31: Despesa mensal aproximada | B31: 15000
A32: Despesa anual aproximada | B32: =B31*12 -> 180000
A33: Reserva de emergência - Já possui? Comente | B33: Sim
A34: Reserva de emergência - Necessidade | B34: 90000
A35: Reserva Adicional - objetivo de curto prazo | B35: 0
A36: Reserva de emergência - Valor atual | B36: 52000
A37: PGBL?
A39: 5. OBJETIVOS E PLANO DE INVESTIMENTOS
A40: Idade na data de contratação da consultoria | B40: =D5 -> 40.09863 | C40: Observações / Comentários
A41: Valor inicial sob consultoria | B41: 300000
A42: Qual a sua fase de vida? (foco financeiro) | B42: Acúmulo de Patrimônio
A43: Quantos anos pretende ficar nesta fase? | B43: 5
A44: Qual é o aporte mensal acordado? | B44: 30000
A45: Qual o dia do aporte acordado? | B45: 15
...

Sheet FUTURO
A1: PLANEJAMENTO INICIAL
B3: Nome: | N3: Data Atual
B4: ='Visão 360°'!A5 -> 0 | N4: =TODAY() -> 46092
B5: Fase de Acúmulo
C7: Qual seu perfil de risco? | G7: Taxa Nominal (a.a.) | I7: Valor Nominal Final | K7: Retorno Total Nominal
C8: Moderado | G8: =(1+G11)*(1+C17)-1 -> 0.113 | I8: =IFERROR(-FV('Base PFi'!C3,M17*12,$C$14,(IF($E$11=0,$C$11,$E$11)),),"") -> 3032664.6 | K8: =IFERROR(I8-C20,"") -> 844664.56
C10: Patrimônio Atual | G10: Taxa Real (a.a.) | I10: Valor Real Final | K10: Retorno Total Real | M10: Idade Atual:
C11: ='Visão 360°'!B15 -> 388000 | G11: {=_xlfn.IFS(C8="Conservador",4%,C8="Moderado",5%,C8="Arrojado",6%,C8="Agressivo",8%)} -> 0.05 | I11: =IFERROR(-FV('Base PFi'!C4,M17*12,$C$14,(IF($E$11=0,$C$11,$E$11)),),"") -> 2529609.4 | K11: =IFERROR(I11-C20,"") -> 341609.38 | M11: ='Visão 360°'!D5 -> 40.09863 | N11: Anos
C13: Aportes mensais acordados: | M13: Idade Objetivo:
C14: ='Visão 360°'!B44 -> 30000 | M14: =M11+'Visão 360°'!B43 -> 45.09863 | N14: Anos
C16: Inflação (IPCA) médio - 20 anos (a.a.) = | M16: Tempo de Contribuição (Anos):
C17: 0.06 | M17: =IFERROR(IF((M14-M11)<0,"",(M14-M11)),"") -> 5 | N17: Anos
C19: Valor Total Investido
C20: =IFERROR(((C14*12)*M17)+(IF($E$11=0,$C$11,$E$11)),"") -> 2188000
B23: Fase de Usufruto
C25: Taxa de Juros real
C26: 0.04
C28: RENDA PASSIVA POTENCIAL (PL)
C29: =C26*I11/12 -> 8432.0313
C31: INSS + Outras receitas
C32: ='Visão 360°'!B52 -> 15000
C34: RENDA PASSIVA POTENCIAL (PL + INSS)
C35: =C32+C29 -> 23432.031
C37: Objetivo Gasto Mensal:
C38: ='Visão 360°'!B50 -> 50000
C40: Superávit / Déficit
C41: =C35-C38 -> -26567.969

Sheet Controle
A1: CONTROLE
E2: Camadas de Proteção | K2: =#REF! -> #REF!
A3: Sucessório | E3: Etapas | F3: Necessidade | G3: Coberto | H3: Nec | I3: Cob
A4: Patrimônio Exposto a Inventário | B4: =SUCESSÓRIO!B23 -> -412000 | E4: RE - 100% | F4: Sim | G4: Não | H4: =IF(Controle!$F4="sim",1,0) -> 1 | I4: =IF(Controle!$G4="sim",1,0) -> 0 | K4: =#REF! -> #REF!
A5: Custo estimado com inventário | B5: =SUCESSÓRIO!B24 -> 0 | E5: Asset Allocation | F5: Sim | G5: Sim | H5: =IF(Controle!$F5="sim",1,0) -> 1 | I5: =IF(Controle!$G5="sim",1,0) -> 1 | K5: =#REF! -> #REF!
A6: Cobertura atual para legado | B6: ='Visão 360°'!B92 -> 600000 | E6: Seguro de Vida | F6: Não | G6: Não | H6: =IF(Controle!$F6="sim",1,0) -> 0 | I6: =IF(Controle!$G6="sim",1,0) -> 0 | K6: =#REF! -> #REF!
A7: Necessidade adicional para inventário | B7: =SUCESSÓRIO!B26 -> 0 | E7: Blindagem Patrimonial | F7: Sim | G7: Sim | H7: =IF(Controle!$F7="sim",1,0) -> 1 | I7: =IF(Controle!$G7="sim",1,0) -> 1 | K7: =K5-K6 -> #REF!
A8: Blindagem | E8: Plano de Saúde | F8: Sim | G8: Sim | H8: =IF(Controle!$F8="sim",1,0) -> 1 | I8: =IF(Controle!$G8="sim",1,0) -> 1 | K8: =#REF! -> #REF!
A9: Proteção Invalidez Ideal (0,5% a.m.) | B9: ='Visão 360°'!B31*200 -> 3000000 | E9: Previdência VGBL | F9: Não | G9: Não | H9: =IF(Controle!$F9="sim",1,0) -> 0 | I9: =IF(Controle!$G9="sim",1,0) -> 0 | K9: =#REF! -> #REF!
A10: Proteção Invalidez Atual | B10: ='Visão 360°'!C64 -> 0 | E10: Cobertura Adicional | F10: Não | G10: Não | H10: =IF(Controle!$F10="sim",1,0) -> 0 | I10: =IF(Controle!$G10="sim",1,0) -> 0
A11: Cobertura adicional | B11: ='Visão 360°'!B73 -> 0
A12: Evolução em relação a liberdade financeira
A13: 45938 | B13: ='Visão 360°'!B15/FUTURO!I8 -> 0.1279403
A15: Aportes acordados
A16: Acordado por mês | B16: ='Visão 360°'!B44 -> 30000
A17: Acordado total | B17: ='Visão 360°'!B47 -> 270000
A18: Total aportado | B18: =SUM(B22:B33) -> 9200 | C18: =MIN($B$18/$B$17,1) -> 0.034074074
A19: Quanto falta | B19: =MAX($B$17-$B$18,0) -> 260800 | C19: =MAX(1-$C$18,0) -> 0.96592593
A20: Quanto superou | B20: =MAX($B$18-$B$17,0) -> 0
A21: Aportes | B21: Efetivo
A22: Novembro | B22: 2000
A23: Dezembro | B23: 4200
A24: Janeiro | B24: 3000
A25: Fevereiro
A26: Mês 5
A27: Mês 6
A28: Mês 7
A29: Mês 8
A30: Mês 9
A31: Mês 10
A32: Mês 11
A33: Mês 12

Sheet Resultados

Sheet SUCESSÓRIO
A1: CHECKUP DE PLANEJAMENTO SUCESSÓRIO (Brasil)
A2: Gerado em 22/09/2025 – Modelo didático (valide exceções com advogado/tabelião).
A4: 1) DADOS E PERGUNTAS ESSENCIAIS
A5: Estado civil | B5: ='Visão 360°'!B76 -> Solteiro
A6: Regime de bens | B6: ='Visão 360°'!B77 -> Não Aplicável
A7: Separação Obrigatória (art. 1.641 CC)? | B7: Não
A8: Aplicar Súmula 377 do STF? (comunicação dos aquestos) | B8: Não
A9: Tem filhos (descendentes)? | B9: Sim
A10: Qtd. de filhos | B10: ='Visão 360°'!B79 -> 1
A11: Ascendentes vivos (pais)? | B11: Sim
A12: Observação (testamento, doações, cláusulas…)
A14: 2) PATRIMÔNIO PARA CÁLCULO
A15: Bens COMUNS (aquestos) – total do casal | B15: ='Visão 360°'!B83 -> 0
A16: Bens PARTICULARES do falecido | B16: ='Visão 360°'!B84 -> -12000
A17: DÍVIDAS dedutíveis do falecido | B17: ='Visão 360°'!B85 -> 400000
A18: Recursos FORA do inventário (seguro de vida com beneficiário, VGBL/prev. privada etc.) – para custear inventário | B18: ='Visão 360°'!B81+'Visão 360°'!B82 -> 600000
A20: 3) CÁLCULO AUTOMÁTICO
A21: Meação do cônjuge/companheiro | B21: =IF(OR(B5="Casado",B5="União estável"), IF(B6="Comunhão Parcial", B15*0.5, IF(B6="Comunhão Universal", (B15+B16)*0.5, IF(B6="Separação Total", 0, IF(B6="Separação Obrigatória", IF(B8="Sim", B15*0.5, 0), 0) ) ) ), 0 ) -> 0
A22: ESPÓLIO BRUTO (vai para inventário) | B22: =IF($B$5="Solteiro", $B$15+$B$16,IF($B$6="Comunhão Parcial", $B$15*0.5 + $B$16,IF($B$6="Comunhão Universal", ($B$15+$B$16)*0.5,IF($B$6="Separação Total", $B$15+$B$16,IF($B$6="Separação Obrigatória", IF($B$8="Sim", $B$15*0.5 + $B$16, $B$15+$B$16), 0))))) -> -12000
A23: ESPÓLIO LÍQUIDO (após dívidas) | B23: =$B$22 - $B$17 -> -412000
A24: CUSTO ESTIMADO DO INVENTÁRIO (20% da base líquida) | B24: =IF($B$23>0, $B$23*0.2, 0) -> 0
A25: Recursos disponíveis para custas (fora do inventário) | B25: =$B$18 -> 600000
A26: NECESSIDADE ADICIONAL para inventário | B26: =MAX(0, $B$24 - $B$25) -> 0

Sheet Base PFi
C2: =(((FUTURO!C17+1)^(1/12))-1) -> 0.0048675506
C3: =(((FUTURO!G8+1)^(1/12))-1) -> 0.0089615054 | E3: IDADE | F3: Ano | G3: Juros | H3: Total Investido | I3: Total Juros | J3: TotalAcumulado | O3: ANO | P3: IDADE | Q3: PL | R3: RENDA ANO | S3: GASTO ANO | T3: GASTO MÊS
C4: =(((FUTURO!G11+1)^(1/12))-1) -> 0.0040741238 | E4: =Tabela1[[#This Row],[Ano]]+FUTURO!$M$11 -> 40.09863 | F4: 0 | G4: =Tabela1[[#This Row],[TotalAcumulado]]-Tabela1[[#This Row],[Total Investido]] -> 0 | H4: =FUTURO!$C$11 -> 388000 | I4: =Tabela1[[#This Row],[Juros]] -> 0 | J4: =-FV(C3,Tabela1[[#This Row],[Ano]]*12,FUTURO!$C$14,FUTURO!$C$11,) -> 388000 | O4: =0 -> 0 | P4: =Tabela4620[[#This Row],[ANO]]+FUTURO!$M$14 -> 45.09863 | Q4: =FUTURO!$I$11 -> 2529609.4 | R4: =FUTURO!$C$26*Tabela4620[[#This Row],[PL]]+(FUTURO!$C$32*12) -> 281184.38 | S4: =FUTURO!$C$38*12 -> 600000 | T4: =FUTURO!C38-V4 -> 50000
E5: =Tabela1[[#This Row],[Ano]]+FUTURO!$M$11 -> 41.09863 | F5: =F4+1 -> 1 | G5: =Tabela1[[#This Row],[TotalAcumulado]]-Tabela1[[#This Row],[Total Investido]] -> 62128.659 | H5: =H4+(FUTURO!$C$14*12) -> 748000 | I5: =Tabela1[[#This Row],[Juros]] -> 62128.659 | J5: =-FV(C3,Tabela1[[#This Row],[Ano]]*12,FUTURO!$C$14,FUTURO!$C$11,) -> 810128.66 | O5: =1+O4 -> 1 | P5: =Tabela4620[[#This Row],[ANO]]+FUTURO!$M$14 -> 46.09863 | Q5: =Q4+R4-S4 -> 2210793.8 | R5: =FUTURO!$C$26*Tabela4620[[#This Row],[PL]]+(FUTURO!$C$32*12) -> 268431.75 | S5: =FUTURO!$C$38*12 -> 600000 | T5: =FUTURO!C38--V5 -> 50000
E6: =Tabela1[[#This Row],[Ano]]+FUTURO!$M$11 -> 42.09863 | F6: =F5+1 -> 2 | G6: =Tabela1[[#This Row],[TotalAcumulado]]-Tabela1[[#This Row],[Total Investido]] -> 171957.86 | H6: =H5+(FUTURO!$C$14*12) -> 1108000 | I6: =Tabela1[[#This Row],[Juros]] -> 171957.86 | J6: =-FV(C3,Tabela1[[#This Row],[Ano]]*12,FUTURO!$C$14,FUTURO!$C$11,) -> 1279957.9 | O6: =1+O5 -> 2 | P6: =Tabela4620[[#This Row],[ANO]]+FUTURO!$M$14 -> 47.09863 | Q6: =Q5+R5-S5 -> 1879225.5 | R6: =FUTURO!$C$26*Tabela4620[[#This Row],[PL]]+(FUTURO!$C$32*12) -> 255169.02 | S6: =FUTURO!$C$38*12 -> 600000 | T6: =FUTURO!C38-V6 -> 50000
E7: =Tabela1[[#This Row],[Ano]]+FUTURO!$M$11 -> 43.09863 | F7: =F6+1 -> 3 | G7: =Tabela1[[#This Row],[TotalAcumulado]]-Tabela1[[#This Row],[Total Investido]] -> 334877.75 | H7: =H6+(FUTURO!$C$14*12) -> 1468000 | I7: =Tabela1[[#This Row],[Juros]] -> 334877.75 | J7: =-FV(C3,Tabela1[[#This Row],[Ano]]*12,FUTURO!$C$14,FUTURO!$C$11,) -> 1802877.8 | O7: =1+O6 -> 3 | P7: =Tabela4620[[#This Row],[ANO]]+FUTURO!$M$14 -> 48.09863 | Q7: =Q6+R6-S6 -> 1534394.5 | R7: =FUTURO!$C$26*Tabela4620[[#This Row],[PL]]+(FUTURO!$C$32*12) -> 241375.78 | S7: =FUTURO!$C$38*12 -> 600000 | T7: =FUTURO!C38-V7 -> 50000
E8: =Tabela1[[#This Row],[Ano]]+FUTURO!$M$11 -> 44.09863 | F8: =F7+1 -> 4 | G8: =Tabela1[[#This Row],[TotalAcumulado]]-Tabela1[[#This Row],[Total Investido]] -> 556887.6 | H8: =H7+(FUTURO!$C$14*12) -> 1828000 | I8: =Tabela1[[#This Row],[Juros]] -> 556887.6 | J8: =-FV(C3,Tabela1[[#This Row],[Ano]]*12,FUTURO!$C$14,FUTURO!$C$11,) -> 2384887.6 | O8: =1+O7 -> 4 | P8: =Tabela4620[[#This Row],[ANO]]+FUTURO!$M$14 -> 49.09863 | Q8: =Q7+R7-S7 -> 1175770.3 | R8: =FUTURO!$C$26*Tabela4620[[#This Row],[PL]]+(FUTURO!$C$32*12) -> 227030.81 | S8: =FUTURO!$C$38*12 -> 600000 | T8: =FUTURO!C38-V8 -> 50000
E9: =Tabela1[[#This Row],[Ano]]+FUTURO!$M$11 -> 45.09863 | F9: =F8+1 -> 5 | G9: =Tabela1[[#This Row],[TotalAcumulado]]-Tabela1[[#This Row],[Total Investido]] -> 844664.56 | H9: =H8+(FUTURO!$C$14*12) -> 2188000 | I9: =Tabela1[[#This Row],[Juros]] -> 844664.56 | J9: =-FV(C3,Tabela1[[#This Row],[Ano]]*12,FUTURO!$C$14,FUTURO!$C$11,) -> 3032664.6 | O9: =1+O8 -> 5 | P9: =Tabela4620[[#This Row],[ANO]]+FUTURO!$M$14 -> 50.09863 | Q9: =Q8+R8-S8 -> 802801.12 | R9: =FUTURO!$C$26*Tabela4620[[#This Row],[PL]]+(FUTURO!$C$32*12) -> 212112.04 | S9: =FUTURO!$C$38*12 -> 600000 | T9: =FUTURO!C38-V9 -> 50000
E10: =Tabela1[[#This Row],[Ano]]+FUTURO!$M$11 -> 46.09863 | F10: =F9+1 -> 6 | G10: =Tabela1[[#This Row],[TotalAcumulado]]-Tabela1[[#This Row],[Total Investido]] -> 1205640.3 | H10: =H9+(FUTURO!$C$14*12) -> 2548000 | I10: =Tabela1[[#This Row],[Juros]] -> 1205640.3 | J10: =-FV(C3,Tabela1[[#This Row],[Ano]]*12,FUTURO!$C$14,FUTURO!$C$11,) -> 3753640.3 | O10: =1+O9 -> 6 | P10: =Tabela4620[[#This Row],[ANO]]+FUTURO!$M$14 -> 51.09863 | Q10: =Q9+R9-S9 -> 414913.17 | R10: =FUTURO!$C$26*Tabela4620[[#This Row],[PL]]+(FUTURO!$C$32*12) -> 196596.53 | S10: =FUTURO!$C$38*12 -> 600000 | T10: =FUTURO!C38-V10 -> 50000
E11: =Tabela1[[#This Row],[Ano]]+FUTURO!$M$11 -> 47.09863 | F11: =F10+1 -> 7 | G11: =Tabela1[[#This Row],[TotalAcumulado]]-Tabela1[[#This Row],[Total Investido]] -> 1648086.3 | H11: =H10+(FUTURO!$C$14*12) -> 2908000 | I11: =Tabela1[[#This Row],[Juros]] -> 1648086.3 | J11: =-FV(C3,Tabela1[[#This Row],[Ano]]*12,FUTURO!$C$14,FUTURO!$C$11,) -> 4556086.3 | O11: =1+O10 -> 7 | P11: =Tabela4620[[#This Row],[ANO]]+FUTURO!$M$14 -> 52.09863 | Q11: =Q10+R10-S10 -> 11509.695 | R11: =FUTURO!$C$26*Tabela4620[[#This Row],[PL]]+(FUTURO!$C$32*12) -> 180460.39 | S11: =FUTURO!$C$38*12 -> 600000 | T11: =FUTURO!C38-V11 -> 50000
E12: =Tabela1[[#This Row],[Ano]]+FUTURO!$M$11 -> 48.09863 | F12: =F11+1 -> 8 | G12: =Tabela1[[#This Row],[TotalAcumulado]]-Tabela1[[#This Row],[Total Investido]] -> 2181208.7 | H12: =H11+(FUTURO!$C$14*12) -> 3268000 | I12: =Tabela1[[#This Row],[Juros]] -> 2181208.7 | J12: =-FV(C3,Tabela1[[#This Row],[Ano]]*12,FUTURO!$C$14,FUTURO!$C$11,) -> 5449208.7 | O12: =1+O11 -> 8 | P12: =Tabela4620[[#This Row],[ANO]]+FUTURO!$M$14 -> 53.09863 | Q12: =Q11+R11-S11 -> -408029.92 | R12: =FUTURO!$C$26*Tabela4620[[#This Row],[PL]]+(FUTURO!$C$32*12) -> 163678.8 | S12: =FUTURO!$C$38*12 -> 600000 | T12: =FUTURO!C38-V12 -> 50000
E13: =Tabela1[[#This Row],[Ano]]+FUTURO!$M$11 -> 49.09863 | F13: =F12+1 -> 9 | G13: =Tabela1[[#This Row],[TotalAcumulado]]-Tabela1[[#This Row],[Total Investido]] -> 2815254 | H13: =H12+(FUTURO!$C$14*12) -> 3628000 | I13: =Tabela1[[#This Row],[Juros]] -> 2815254 | J13: =-FV(C3,Tabela1[[#This Row],[Ano]]*12,FUTURO!$C$14,FUTURO!$C$11,) -> 6443254 | O13: =1+O12 -> 9 | P13: =Tabela4620[[#This Row],[ANO]]+FUTURO!$M$14 -> 54.09863 | Q13: =Q12+R12-S12 -> -844351.11 | R13: =FUTURO!$C$26*Tabela4620[[#This Row],[PL]]+(FUTURO!$C$32*12) -> 146225.96 | S13: =FUTURO!$C$38*12 -> 600000 | T13: =FUTURO!C38-V13 -> 50000
E14: =Tabela1[[#This Row],[Ano]]+FUTURO!$M$11 -> 50.09863 | F14: =F13+1 -> 10 | G14: =Tabela1[[#This Row],[TotalAcumulado]]-Tabela1[[#This Row],[Total Investido]] -> 3561626.3 | H14: =H13+(FUTURO!$C$14*12) -> 3988000 | I14: =Tabela1[[#This Row],[Juros]] -> 3561626.3 | J14: =-FV(C3,Tabela1[[#This Row],[Ano]]*12,FUTURO!$C$14,FUTURO!$C$11,) -> 7549626.3 | O14: =1+O13 -> 10 | P14: =Tabela4620[[#This Row],[ANO]]+FUTURO!$M$14 -> 55.09863 | Q14: =Q13+R13-S13 -> -1298125.2 | R14: =FUTURO!$C$26*Tabela4620[[#This Row],[PL]]+(FUTURO!$C$32*12) -> 128074.99 | S14: =FUTURO!$C$38*12 -> 600000 | T14: =FUTURO!C38-V14 -> 50000
E15: =Tabela1[[#This Row],[Ano]]+FUTURO!$M$11 -> 51.09863 | F15: =F14+1 -> 11 | G15: =Tabela1[[#This Row],[TotalAcumulado]]-Tabela1[[#This Row],[Total Investido]] -> 4433018.8 | H15: =H14+(FUTURO!$C$14*12) -> 4348000 | I15: =Tabela1[[#This Row],[Juros]] -> 4433018.8 | J15: =-FV(C3,Tabela1[[#This Row],[Ano]]*12,FUTURO!$C$14,FUTURO!$C$11,) -> 8781018.8 | O15: =1+O14 -> 11 | P15: =Tabela4620[[#This Row],[ANO]]+FUTURO!$M$14 -> 56.09863 | Q15: =Q14+R14-S14 -> -1770050.2 | R15: =FUTURO!$C$26*Tabela4620[[#This Row],[PL]]+(FUTURO!$C$32*12) -> 109197.99 | S15: =FUTURO!$C$38*12 -> 600000 | T15: =FUTURO!C38-V15 -> 50000
E16: =Tabela1[[#This Row],[Ano]]+FUTURO!$M$11 -> 52.09863 | F16: =F15+1 -> 12 | G16: =Tabela1[[#This Row],[TotalAcumulado]]-Tabela1[[#This Row],[Total Investido]] -> 5443558.6 | H16: =H15+(FUTURO!$C$14*12) -> 4708000 | I16: =Tabela1[[#This Row],[Juros]] -> 5443558.6 | J16: =-FV(C3,Tabela1[[#This Row],[Ano]]*12,FUTURO!$C$14,FUTURO!$C$11,) -> 10151559 | O16: =1+O15 -> 12 | P16: =Tabela4620[[#This Row],[ANO]]+FUTURO!$M$14 -> 57.09863 | Q16: =Q15+R15-S15 -> -2260852.2 | R16: =FUTURO!$C$26*Tabela4620[[#This Row],[PL]]+(FUTURO!$C$32*12) -> 89565.913 | S16: =FUTURO!$C$38*12 -> 600000 | T16: =FUTURO!C38-V16 -> 50000
E17: =Tabela1[[#This Row],[Ano]]+FUTURO!$M$11 -> 53.09863 | F17: =F16+1 -> 13 | G17: =Tabela1[[#This Row],[TotalAcumulado]]-Tabela1[[#This Row],[Total Investido]] -> 6608969.3 | H17: =H16+(FUTURO!$C$14*12) -> 5068000 | I17: =Tabela1[[#This Row],[Juros]] -> 6608969.3 | J17: =-FV(C3,Tabela1[[#This Row],[Ano]]*12,FUTURO!$C$14,FUTURO!$C$11,) -> 11676969 | O17: =1+O16 -> 13 | P17: =Tabela4620[[#This Row],[ANO]]+FUTURO!$M$14 -> 58.09863 | Q17: =Q16+R16-S16 -> -2771286.3 | R17: =FUTURO!$C$26*Tabela4620[[#This Row],[PL]]+(FUTURO!$C$32*12) -> 69148.55 | S17: =FUTURO!$C$38*12 -> 600000 | T17: =FUTURO!C38-V17 -> 50000
E18: =Tabela1[[#This Row],[Ano]]+FUTURO!$M$11 -> 54.09863 | F18: =F17+1 -> 14 | G18: =Tabela1[[#This Row],[TotalAcumulado]]-Tabela1[[#This Row],[Total Investido]] -> 7946751.5 | H18: =H17+(FUTURO!$C$14*12) -> 5428000 | I18: =Tabela1[[#This Row],[Juros]] -> 7946751.5 | J18: =-FV(C3,Tabela1[[#This Row],[Ano]]*12,FUTURO!$C$14,FUTURO!$C$11,) -> 13374752 | O18: =1+O17 -> 14 | P18: =Tabela4620[[#This Row],[ANO]]+FUTURO!$M$14 -> 59.09863 | Q18: =Q17+R17-S17 -> -3302137.7 | R18: =FUTURO!$C$26*Tabela4620[[#This Row],[PL]]+(FUTURO!$C$32*12) -> 47914.492 | S18: =FUTURO!$C$38*12 -> 600000 | T18: =FUTURO!C38-V18 -> 50000
E19: =Tabela1[[#This Row],[Ano]]+FUTURO!$M$11 -> 55.09863 | F19: =F18+1 -> 15 | G19: =Tabela1[[#This Row],[TotalAcumulado]]-Tabela1[[#This Row],[Total Investido]] -> 9476383.1 | H19: =H18+(FUTURO!$C$14*12) -> 5788000 | I19: =Tabela1[[#This Row],[Juros]] -> 9476383.1 | J19: =-FV(C3,Tabela1[[#This Row],[Ano]]*12,FUTURO!$C$14,FUTURO!$C$11,) -> 15264383 | O19: =1+O18 -> 15 | P19: =Tabela4620[[#This Row],[ANO]]+FUTURO!$M$14 -> 60.09863 | Q19: =Q18+R18-S18 -> -3854223.2 | R19: =FUTURO!$C$26*Tabela4620[[#This Row],[PL]]+(FUTURO!$C$32*12) -> 25831.071 | S19: =FUTURO!$C$38*12 -> 600000 | T19: =FUTURO!C38-V19 -> 50000
E20: =Tabela1[[#This Row],[Ano]]+FUTURO!$M$11 -> 56.09863 | F20: =F19+1 -> 16 | G20: =Tabela1[[#This Row],[TotalAcumulado]]-Tabela1[[#This Row],[Total Investido]] -> 11219543 | H20: =H19+(FUTURO!$C$14*12) -> 6148000 | I20: =Tabela1[[#This Row],[Juros]] -> 11219543 | J20: =-FV(C3,Tabela1[[#This Row],[Ano]]*12,FUTURO!$C$14,FUTURO!$C$11,) -> 17367543 | O20: =1+O19 -> 16 | P20: =Tabela4620[[#This Row],[ANO]]+FUTURO!$M$14 -> 61.09863 | Q20: =Q19+R19-S19 -> -4428392.1 | R20: =FUTURO!$C$26*Tabela4620[[#This Row],[PL]]+(FUTURO!$C$32*12) -> 2864.3142 | S20: =FUTURO!$C$38*12 -> 600000 | T20: =FUTURO!C38-V20 -> 50000
E21: =Tabela1[[#This Row],[Ano]]+FUTURO!$M$11 -> 57.09863 | F21: =F20+1 -> 17 | G21: =Tabela1[[#This Row],[TotalAcumulado]]-Tabela1[[#This Row],[Total Investido]] -> 13200360 | H21: =H20+(FUTURO!$C$14*12) -> 6508000 | I21: =Tabela1[[#This Row],[Juros]] -> 13200360 | J21: =-FV(C3,Tabela1[[#This Row],[Ano]]*12,FUTURO!$C$14,FUTURO!$C$11,) -> 19708360 | O21: =1+O20 -> 17 | P21: =Tabela4620[[#This Row],[ANO]]+FUTURO!$M$14 -> 62.09863 | Q21: =Q20+R20-S20 -> -5025527.8 | R21: =FUTURO!$C$26*Tabela4620[[#This Row],[PL]]+(FUTURO!$C$32*12) -> -21021.113 | S21: =FUTURO!$C$38*12 -> 600000 | T21: =FUTURO!C38-V21 -> 50000
E22: =Tabela1[[#This Row],[Ano]]+FUTURO!$M$11 -> 58.09863 | F22: =F21+1 -> 18 | G22: =Tabela1[[#This Row],[TotalAcumulado]]-Tabela1[[#This Row],[Total Investido]] -> 15445689 | H22: =H21+(FUTURO!$C$14*12) -> 6868000 | I22: =Tabela1[[#This Row],[Juros]] -> 15445689 | J22: =-FV(C3,Tabela1[[#This Row],[Ano]]*12,FUTURO!$C$14,FUTURO!$C$11,) -> 22313689 | O22: =1+O21 -> 18 | P22: =Tabela4620[[#This Row],[ANO]]+FUTURO!$M$14 -> 63.09863 | Q22: =Q21+R21-S21 -> -5646548.9 | R22: =FUTURO!$C$26*Tabela4620[[#This Row],[PL]]+(FUTURO!$C$32*12) -> -45861.958 | S22: =FUTURO!$C$38*12 -> 600000 | T22: =FUTURO!C38-V22 -> 50000
E23: =Tabela1[[#This Row],[Ano]]+FUTURO!$M$11 -> 59.09863 | F23: =F22+1 -> 19 | G23: =Tabela1[[#This Row],[TotalAcumulado]]-Tabela1[[#This Row],[Total Investido]] -> 17985421 | H23: =H22+(FUTURO!$C$14*12) -> 7228000 | I23: =Tabela1[[#This Row],[Juros]] -> 17985421 | J23: =-FV(C3,Tabela1[[#This Row],[Ano]]*12,FUTURO!$C$14,FUTURO!$C$11,) -> 25213421 | O23: =1+O22 -> 19 | P23: =Tabela4620[[#This Row],[ANO]]+FUTURO!$M$14 -> 64.09863 | Q23: =Q22+R22-S22 -> -6292410.9 | R23: =FUTURO!$C$26*Tabela4620[[#This Row],[PL]]+(FUTURO!$C$32*12) -> -71696.436 | S23: =FUTURO!$C$38*12 -> 600000 | T23: =FUTURO!C38-V23 -> 50000
E24: =Tabela1[[#This Row],[Ano]]+FUTURO!$M$11 -> 60.09863 | F24: =F23+1 -> 20 | G24: =Tabela1[[#This Row],[TotalAcumulado]]-Tabela1[[#This Row],[Total Investido]] -> 20852822 | H24: =H23+(FUTURO!$C$14*12) -> 7588000 | I24: =Tabela1[[#This Row],[Juros]] -> 20852822 | J24: =-FV(C3,Tabela1[[#This Row],[Ano]]*12,FUTURO!$C$14,FUTURO!$C$11,) -> 28440822 | O24: =1+O23 -> 20 | P24: =Tabela4620[[#This Row],[ANO]]+FUTURO!$M$14 -> 65.09863 | Q24: =Q23+R23-S23 -> -6964107.3 | R24: =FUTURO!$C$26*Tabela4620[[#This Row],[PL]]+(FUTURO!$C$32*12) -> -98564.294 | S24: =FUTURO!$C$38*12 -> 600000 | T24: =FUTURO!C38-V24 -> 50000
E25: =Tabela1[[#This Row],[Ano]]+FUTURO!$M$11 -> 61.09863 | F25: =F24+1 -> 21 | G25: =Tabela1[[#This Row],[TotalAcumulado]]-Tabela1[[#This Row],[Total Investido]] -> 24084920 | H25: =H24+(FUTURO!$C$14*12) -> 7948000 | I25: =Tabela1[[#This Row],[Juros]] -> 24084920 | J25: =-FV(C3,Tabela1[[#This Row],[Ano]]*12,FUTURO!$C$14,FUTURO!$C$11,) -> 32032920 | O25: =1+O24 -> 21 | P25: =Tabela4620[[#This Row],[ANO]]+FUTURO!$M$14 -> 66.09863 | Q25: =Q24+R24-S24 -> -7662671.6 | R25: =FUTURO!$C$26*Tabela4620[[#This Row],[PL]]+(FUTURO!$C$32*12) -> -126506.87 | S25: =FUTURO!$C$38*12 -> 600000 | T25: =FUTURO!C38-V25 -> 50000
E26: =Tabela1[[#This Row],[Ano]]+FUTURO!$M$11 -> 62.09863 | F26: =F25+1 -> 22 | G26: =Tabela1[[#This Row],[TotalAcumulado]]-Tabela1[[#This Row],[Total Investido]] -> 27722924 | H26: =H25+(FUTURO!$C$14*12) -> 8308000 | I26: =Tabela1[[#This Row],[Juros]] -> 27722924 | J26: =-FV(C3,Tabela1[[#This Row],[Ano]]*12,FUTURO!$C$14,FUTURO!$C$11,) -> 36030924 | O26: =1+O25 -> 22 | P26: =Tabela4620[[#This Row],[ANO]]+FUTURO!$M$14 -> 67.09863 | Q26: =Q25+R25-S25 -> -8389178.5 | R26: =FUTURO!$C$26*Tabela4620[[#This Row],[PL]]+(FUTURO!$C$32*12) -> -155567.14 | S26: =FUTURO!$C$38*12 -> 600000 | T26: =FUTURO!C38-V26 -> 50000
E27: =Tabela1[[#This Row],[Ano]]+FUTURO!$M$11 -> 63.09863 | F27: =F26+1 -> 23 | G27: =Tabela1[[#This Row],[TotalAcumulado]]-Tabela1[[#This Row],[Total Investido]] -> 31812704 | H27: =H26+(FUTURO!$C$14*12) -> 8668000 | I27: =Tabela1[[#This Row],[Juros]] -> 31812704 | J27: =-FV(C3,Tabela1[[#This Row],[Ano]]*12,FUTURO!$C$14,FUTURO!$C$11,) -> 40480704 | O27: =1+O26 -> 23 | P27: =Tabela4620[[#This Row],[ANO]]+FUTURO!$M$14 -> 68.09863 | Q27: =Q26+R26-S26 -> -9144745.6 | R27: =FUTURO!$C$26*Tabela4620[[#This Row],[PL]]+(FUTURO!$C$32*12) -> -185789.83 | S27: =FUTURO!$C$38*12 -> 600000 | T27: =FUTURO!C38-V27 -> 50000
E28: =Tabela1[[#This Row],[Ano]]+FUTURO!$M$11 -> 64.09863 | F28: =F27+1 -> 24 | G28: =Tabela1[[#This Row],[TotalAcumulado]]-Tabela1[[#This Row],[Total Investido]] -> 36405308 | H28: =H27+(FUTURO!$C$14*12) -> 9028000 | I28: =Tabela1[[#This Row],[Juros]] -> 36405308 | J28: =-FV(C3,Tabela1[[#This Row],[Ano]]*12,FUTURO!$C$14,FUTURO!$C$11,) -> 45433308 | O28: =1+O27 -> 24 | P28: =Tabela4620[[#This Row],[ANO]]+FUTURO!$M$14 -> 69.09863 | Q28: =Q27+R27-S27 -> -9930535.5 | R28: =FUTURO!$C$26*Tabela4620[[#This Row],[PL]]+(FUTURO!$C$32*12) -> -217221.42 | S28: =FUTURO!$C$38*12 -> 600000 | T28: =FUTURO!C38-V28 -> 50000
E29: =Tabela1[[#This Row],[Ano]]+FUTURO!$M$11 -> 65.09863 | F29: =F28+1 -> 25 | G29: =Tabela1[[#This Row],[TotalAcumulado]]-Tabela1[[#This Row],[Total Investido]] -> 41557556 | H29: =H28+(FUTURO!$C$14*12) -> 9388000 | I29: =Tabela1[[#This Row],[Juros]] -> 41557556 | J29: =-FV(C3,Tabela1[[#This Row],[Ano]]*12,FUTURO!$C$14,FUTURO!$C$11,) -> 50945556 | O29: =1+O28 -> 25 | P29: =Tabela4620[[#This Row],[ANO]]+FUTURO!$M$14 -> 70.09863 | Q29: =Q28+R28-S28 -> -10747757 | R29: =FUTURO!$C$26*Tabela4620[[#This Row],[PL]]+(FUTURO!$C$32*12) -> -249910.28 | S29: =FUTURO!$C$38*12 -> 600000 | T29: =FUTURO!C38-V29 -> 50000
E30: =Tabela1[[#This Row],[Ano]]+FUTURO!$M$11 -> 66.09863 | F30: =F29+1 -> 26 | G30: =Tabela1[[#This Row],[TotalAcumulado]]-Tabela1[[#This Row],[Total Investido]] -> 47332689 | H30: =H29+(FUTURO!$C$14*12) -> 9748000 | I30: =Tabela1[[#This Row],[Juros]] -> 47332689 | J30: =-FV(C3,Tabela1[[#This Row],[Ano]]*12,FUTURO!$C$14,FUTURO!$C$11,) -> 57080689 | O30: =1+O29 -> 26 | P30: =Tabela4620[[#This Row],[ANO]]+FUTURO!$M$14 -> 71.09863 | Q30: =Q29+R29-S29 -> -11597667 | R30: =FUTURO!$C$26*Tabela4620[[#This Row],[PL]]+(FUTURO!$C$32*12) -> -283906.69 | S30: =FUTURO!$C$38*12 -> 600000 | T30: =FUTURO!C38-V30 -> 50000
O31: =1+O30 -> 27 | P31: =Tabela4620[[#This Row],[ANO]]+FUTURO!$M$14 -> 72.09863 | Q31: =Q30+R30-S30 -> -12481574 | R31: =FUTURO!$C$26*Tabela4620[[#This Row],[PL]]+(FUTURO!$C$32*12) -> -319262.95 | S31: =FUTURO!$C$38*12 -> 600000 | T31: =FUTURO!C38-V31 -> 50000
O32: =1+O31 -> 28 | P32: =Tabela4620[[#This Row],[ANO]]+FUTURO!$M$14 -> 73.09863 | Q32: =Q31+R31-S31 -> -13400837 | R32: =FUTURO!$C$26*Tabela4620[[#This Row],[PL]]+(FUTURO!$C$32*12) -> -356033.47 | S32: =FUTURO!$C$38*12 -> 600000 | T32: =FUTURO!C38-V32 -> 50000
O33: =1+O32 -> 29 | P33: =Tabela4620[[#This Row],[ANO]]+FUTURO!$M$14 -> 74.09863 | Q33: =Q32+R32-S32 -> -14356870 | R33: =FUTURO!$C$26*Tabela4620[[#This Row],[PL]]+(FUTURO!$C$32*12) -> -394274.81 | S33: =FUTURO!$C$38*12 -> 600000 | T33: =FUTURO!C38-V33 -> 50000
O34: =1+O33 -> 30 | P34: =Tabela4620[[#This Row],[ANO]]+FUTURO!$M$14 -> 75.09863 | Q34: =Q33+R33-S33 -> -15351145 | R34: =FUTURO!$C$26*Tabela4620[[#This Row],[PL]]+(FUTURO!$C$32*12) -> -434045.8 | S34: =FUTURO!$C$38*12 -> 600000 | T34: =FUTURO!C38-V34 -> 50000
O35: =1+O34 -> 31 | P35: =Tabela4620[[#This Row],[ANO]]+FUTURO!$M$14 -> 76.09863 | Q35: =Q34+R34-S34 -> -16385191 | R35: =FUTURO!$C$26*Tabela4620[[#This Row],[PL]]+(FUTURO!$C$32*12) -> -475407.64 | S35: =FUTURO!$C$38*12 -> 600000 | T35: =FUTURO!C38-V35 -> 50000
O36: =1+O35 -> 32 | P36: =Tabela4620[[#This Row],[ANO]]+FUTURO!$M$14 -> 77.09863 | Q36: =Q35+R35-S35 -> -17460599 | R36: =FUTURO!$C$26*Tabela4620[[#This Row],[PL]]+(FUTURO!$C$32*12) -> -518423.94 | S36: =FUTURO!$C$38*12 -> 600000 | T36: =FUTURO!C38-V36 -> 50000
O37: =1+O36 -> 33 | P37: =Tabela4620[[#This Row],[ANO]]+FUTURO!$M$14 -> 78.09863 | Q37: =Q36+R36-S36 -> -18579022 | R37: =FUTURO!$C$26*Tabela4620[[#This Row],[PL]]+(FUTURO!$C$32*12) -> -563160.9 | S37: =FUTURO!$C$38*12 -> 600000 | T37: =FUTURO!C38-V37 -> 50000
O38: =1+O37 -> 34 | P38: =Tabela4620[[#This Row],[ANO]]+FUTURO!$M$14 -> 79.09863 | Q38: =Q37+R37-S37 -> -19742183 | R38: =FUTURO!$C$26*Tabela4620[[#This Row],[PL]]+(FUTURO!$C$32*12) -> -609687.33 | S38: =FUTURO!$C$38*12 -> 600000 | T38: =FUTURO!C38-V38 -> 50000
O39: =1+O38 -> 35 | P39: =Tabela4620[[#This Row],[ANO]]+FUTURO!$M$14 -> 80.09863 | Q39: =Q38+R38-S38 -> -20951871 | R39: =FUTURO!$C$26*Tabela4620[[#This Row],[PL]]+(FUTURO!$C$32*12) -> -658074.83 | S39: =FUTURO!$C$38*12 -> 600000 | T39: =FUTURO!C38-V39 -> 50000
O40: =1+O39 -> 36 | P40: =Tabela4620[[#This Row],[ANO]]+FUTURO!$M$14 -> 81.09863 | Q40: =Q39+R39-S39 -> -22209946 | R40: =FUTURO!$C$26*Tabela4620[[#This Row],[PL]]+(FUTURO!$C$32*12) -> -708397.82 | S40: =FUTURO!$C$38*12 -> 600000 | T40: =FUTURO!C38-V40 -> 50000
O41: =1+O40 -> 37 | P41: =Tabela4620[[#This Row],[ANO]]+FUTURO!$M$14 -> 82.09863 | Q41: =Q40+R40-S40 -> -23518343 | R41: =FUTURO!$C$26*Tabela4620[[#This Row],[PL]]+(FUTURO!$C$32*12) -> -760733.73 | S41: =FUTURO!$C$38*12 -> 600000 | T41: =FUTURO!C38-V41 -> 50000
...
